Traceback (most recent call last):
  File "queue_process.py", line 96, in join_queue
    results = loop.run_until_complete(all_groups)
  File "/usr/lib/python3.6/asyncio/base_events.py", line 471, in run_until_complete
    self.run_forever()
  File "/usr/lib/python3.6/asyncio/base_events.py", line 438, in run_forever
    self._run_once()
  File "/usr/lib/python3.6/asyncio/base_events.py", line 1415, in _run_once
    event_list = self._selector.select(timeout)
  File "/usr/lib/python3.6/selectors.py", line 445, in select
    fd_event_list = self._epoll.poll(timeout, max_ev)
KeyboardInterrupt
Traceback (most recent call last):
  File "/usr/local/lib/python3.6/dist-packages/websockets/protocol.py", line 795, in transfer_data
    message = await self.read_message()
  File "/usr/local/lib/python3.6/dist-packages/websockets/protocol.py", line 863, in read_message
    frame = await self.read_data_frame(max_size=self.max_size)
  File "/usr/local/lib/python3.6/dist-packages/websockets/protocol.py", line 938, in read_data_frame
    frame = await self.read_frame(max_size)
  File "/usr/local/lib/python3.6/dist-packages/websockets/protocol.py", line 1018, in read_frame
    extensions=self.extensions,
  File "/usr/local/lib/python3.6/dist-packages/websockets/framing.py", line 121, in read
    data = await reader(2)
  File "/usr/lib/python3.6/asyncio/streams.py", line 672, in readexactly
    raise IncompleteReadError(incomplete, n)
asyncio.streams.IncompleteReadError: 0 bytes read on a total of 2 expected bytes

The above exception was the direct cause of the following exception:

Traceback (most recent call last):
  File "queue_process.py", line 37, in queue_client
    await socket.send("done")
  File "/usr/local/lib/python3.6/dist-packages/websockets/protocol.py", line 530, in send
    await self.ensure_open()
  File "/usr/local/lib/python3.6/dist-packages/websockets/protocol.py", line 771, in ensure_open
    raise self.connection_closed_exc()
websockets.exceptions.ConnectionClosedError: code = 1006 (connection closed abnormally [internal]), no reason
Traceback (most recent call last):
  File "/usr/local/lib/python3.6/dist-packages/websockets/protocol.py", line 795, in transfer_data
    message = await self.read_message()
  File "/usr/local/lib/python3.6/dist-packages/websockets/protocol.py", line 863, in read_message
    frame = await self.read_data_frame(max_size=self.max_size)
  File "/usr/local/lib/python3.6/dist-packages/websockets/protocol.py", line 938, in read_data_frame
    frame = await self.read_frame(max_size)
  File "/usr/local/lib/python3.6/dist-packages/websockets/protocol.py", line 1018, in read_frame
    extensions=self.extensions,
  File "/usr/local/lib/python3.6/dist-packages/websockets/framing.py", line 121, in read
    data = await reader(2)
  File "/usr/lib/python3.6/asyncio/streams.py", line 674, in readexactly
    yield from self._wait_for_data('readexactly')
  File "/usr/lib/python3.6/asyncio/streams.py", line 464, in _wait_for_data
    yield from self._waiter
concurrent.futures._base.CancelledError

The above exception was the direct cause of the following exception:

Traceback (most recent call last):
  File "queue_process.py", line 37, in queue_client
    await socket.send("done")
  File "/usr/local/lib/python3.6/dist-packages/websockets/protocol.py", line 530, in send
    await self.ensure_open()
  File "/usr/local/lib/python3.6/dist-packages/websockets/protocol.py", line 771, in ensure_open
    raise self.connection_closed_exc()
websockets.exceptions.ConnectionClosedError: code = 1006 (connection closed abnormally [internal]), no reason
Traceback (most recent call last):
  File "/usr/local/lib/python3.6/dist-packages/websockets/protocol.py", line 795, in transfer_data
    message = await self.read_message()
  File "/usr/local/lib/python3.6/dist-packages/websockets/protocol.py", line 863, in read_message
    frame = await self.read_data_frame(max_size=self.max_size)
  File "/usr/local/lib/python3.6/dist-packages/websockets/protocol.py", line 938, in read_data_frame
    frame = await self.read_frame(max_size)
  File "/usr/local/lib/python3.6/dist-packages/websockets/protocol.py", line 1018, in read_frame
    extensions=self.extensions,
  File "/usr/local/lib/python3.6/dist-packages/websockets/framing.py", line 121, in read
    data = await reader(2)
  File "/usr/lib/python3.6/asyncio/streams.py", line 674, in readexactly
    yield from self._wait_for_data('readexactly')
  File "/usr/lib/python3.6/asyncio/streams.py", line 464, in _wait_for_data
    yield from self._waiter
concurrent.futures._base.CancelledError

The above exception was the direct cause of the following exception:

Traceback (most recent call last):
  File "queue_process.py", line 37, in queue_client
    await socket.send("done")
  File "/usr/local/lib/python3.6/dist-packages/websockets/protocol.py", line 530, in send
    await self.ensure_open()
  File "/usr/local/lib/python3.6/dist-packages/websockets/protocol.py", line 771, in ensure_open
    raise self.connection_closed_exc()
websockets.exceptions.ConnectionClosedError: code = 1006 (connection closed abnormally [internal]), no reason
Traceback (most recent call last):
  File "/usr/local/lib/python3.6/dist-packages/websockets/protocol.py", line 795, in transfer_data
    message = await self.read_message()
  File "/usr/local/lib/python3.6/dist-packages/websockets/protocol.py", line 863, in read_message
    frame = await self.read_data_frame(max_size=self.max_size)
  File "/usr/local/lib/python3.6/dist-packages/websockets/protocol.py", line 938, in read_data_frame
    frame = await self.read_frame(max_size)
  File "/usr/local/lib/python3.6/dist-packages/websockets/protocol.py", line 1018, in read_frame
    extensions=self.extensions,
  File "/usr/local/lib/python3.6/dist-packages/websockets/framing.py", line 121, in read
    data = await reader(2)
  File "/usr/lib/python3.6/asyncio/streams.py", line 674, in readexactly
    yield from self._wait_for_data('readexactly')
  File "/usr/lib/python3.6/asyncio/streams.py", line 464, in _wait_for_data
    yield from self._waiter
concurrent.futures._base.CancelledError

The above exception was the direct cause of the following exception:

Traceback (most recent call last):
  File "queue_process.py", line 37, in queue_client
    await socket.send("done")
  File "/usr/local/lib/python3.6/dist-packages/websockets/protocol.py", line 530, in send
    await self.ensure_open()
  File "/usr/local/lib/python3.6/dist-packages/websockets/protocol.py", line 771, in ensure_open
    raise self.connection_closed_exc()
websockets.exceptions.ConnectionClosedError: code = 1006 (connection closed abnormally [internal]), no reason
Traceback (most recent call last):
  File "/usr/local/lib/python3.6/dist-packages/websockets/protocol.py", line 795, in transfer_data
    message = await self.read_message()
  File "/usr/local/lib/python3.6/dist-packages/websockets/protocol.py", line 863, in read_message
    frame = await self.read_data_frame(max_size=self.max_size)
  File "/usr/local/lib/python3.6/dist-packages/websockets/protocol.py", line 938, in read_data_frame
    frame = await self.read_frame(max_size)
  File "/usr/local/lib/python3.6/dist-packages/websockets/protocol.py", line 1018, in read_frame
    extensions=self.extensions,
  File "/usr/local/lib/python3.6/dist-packages/websockets/framing.py", line 121, in read
    data = await reader(2)
  File "/usr/lib/python3.6/asyncio/streams.py", line 674, in readexactly
    yield from self._wait_for_data('readexactly')
  File "/usr/lib/python3.6/asyncio/streams.py", line 464, in _wait_for_data
    yield from self._waiter
concurrent.futures._base.CancelledError

The above exception was the direct cause of the following exception:

Traceback (most recent call last):
  File "queue_process.py", line 37, in queue_client
    await socket.send("done")
  File "/usr/local/lib/python3.6/dist-packages/websockets/protocol.py", line 530, in send
    await self.ensure_open()
  File "/usr/local/lib/python3.6/dist-packages/websockets/protocol.py", line 771, in ensure_open
    raise self.connection_closed_exc()
websockets.exceptions.ConnectionClosedError: code = 1006 (connection closed abnormally [internal]), no reason
Traceback (most recent call last):
  File "/usr/local/lib/python3.6/dist-packages/websockets/protocol.py", line 795, in transfer_data
    message = await self.read_message()
  File "/usr/local/lib/python3.6/dist-packages/websockets/protocol.py", line 863, in read_message
    frame = await self.read_data_frame(max_size=self.max_size)
  File "/usr/local/lib/python3.6/dist-packages/websockets/protocol.py", line 938, in read_data_frame
    frame = await self.read_frame(max_size)
  File "/usr/local/lib/python3.6/dist-packages/websockets/protocol.py", line 1018, in read_frame
    extensions=self.extensions,
  File "/usr/local/lib/python3.6/dist-packages/websockets/framing.py", line 121, in read
    data = await reader(2)
  File "/usr/lib/python3.6/asyncio/streams.py", line 674, in readexactly
    yield from self._wait_for_data('readexactly')
  File "/usr/lib/python3.6/asyncio/streams.py", line 464, in _wait_for_data
    yield from self._waiter
concurrent.futures._base.CancelledError

The above exception was the direct cause of the following exception:

Traceback (most recent call last):
  File "queue_process.py", line 37, in queue_client
    await socket.send("done")
  File "/usr/local/lib/python3.6/dist-packages/websockets/protocol.py", line 530, in send
    await self.ensure_open()
  File "/usr/local/lib/python3.6/dist-packages/websockets/protocol.py", line 771, in ensure_open
    raise self.connection_closed_exc()
websockets.exceptions.ConnectionClosedError: code = 1006 (connection closed abnormally [internal]), no reason
Traceback (most recent call last):
  File "/usr/local/lib/python3.6/dist-packages/websockets/protocol.py", line 795, in transfer_data
    message = await self.read_message()
  File "/usr/local/lib/python3.6/dist-packages/websockets/protocol.py", line 863, in read_message
    frame = await self.read_data_frame(max_size=self.max_size)
  File "/usr/local/lib/python3.6/dist-packages/websockets/protocol.py", line 938, in read_data_frame
    frame = await self.read_frame(max_size)
  File "/usr/local/lib/python3.6/dist-packages/websockets/protocol.py", line 1018, in read_frame
    extensions=self.extensions,
  File "/usr/local/lib/python3.6/dist-packages/websockets/framing.py", line 121, in read
    data = await reader(2)
  File "/usr/lib/python3.6/asyncio/streams.py", line 674, in readexactly
    yield from self._wait_for_data('readexactly')
  File "/usr/lib/python3.6/asyncio/streams.py", line 464, in _wait_for_data
    yield from self._waiter
concurrent.futures._base.CancelledError

The above exception was the direct cause of the following exception:

Traceback (most recent call last):
  File "queue_process.py", line 37, in queue_client
    await socket.send("done")
  File "/usr/local/lib/python3.6/dist-packages/websockets/protocol.py", line 530, in send
    await self.ensure_open()
  File "/usr/local/lib/python3.6/dist-packages/websockets/protocol.py", line 771, in ensure_open
    raise self.connection_closed_exc()
websockets.exceptions.ConnectionClosedError: code = 1006 (connection closed abnormally [internal]), no reason
Traceback (most recent call last):
  File "queue_process.py", line 21, in queue_client
    async with websockets.connect("ws://"+server_ip+":"+str(QUEUE_PORT)) as socket:
  File "/usr/local/lib/python3.6/dist-packages/websockets/client.py", line 519, in __aenter__
    return await self
  File "/usr/local/lib/python3.6/dist-packages/websockets/client.py", line 537, in __await_impl__
    transport, protocol = await self._create_connection()
  File "/usr/lib/python3.6/asyncio/base_events.py", line 794, in create_connection
    raise exceptions[0]
  File "/usr/lib/python3.6/asyncio/base_events.py", line 781, in create_connection
    yield from self.sock_connect(sock, address)
  File "/usr/lib/python3.6/asyncio/selector_events.py", line 439, in sock_connect
    return (yield from fut)
  File "/usr/lib/python3.6/asyncio/selector_events.py", line 469, in _sock_connect_cb
    raise OSError(err, 'Connect call failed %s' % (address,))
ConnectionRefusedError: [Errno 111] Connect call failed ('202.92.132.191', 10015)
Traceback (most recent call last):
  File "/home/netmesh/shitty_netmesh/netmesh-rfc6349-client/queue_process.py", line 96, in join_queue
    results = loop.run_until_complete(all_groups)
  File "/usr/lib/python3.6/asyncio/base_events.py", line 471, in run_until_complete
    self.run_forever()
  File "/usr/lib/python3.6/asyncio/base_events.py", line 438, in run_forever
    self._run_once()
  File "/usr/lib/python3.6/asyncio/base_events.py", line 1415, in _run_once
    event_list = self._selector.select(timeout)
  File "/usr/lib/python3.6/selectors.py", line 445, in select
    fd_event_list = self._epoll.poll(timeout, max_ev)
KeyboardInterrupt
Traceback (most recent call last):
  File "/home/netmesh/shitty_netmesh/netmesh-rfc6349-client/queue_process.py", line 96, in join_queue
    results = loop.run_until_complete(all_groups)
  File "/usr/lib/python3.6/asyncio/base_events.py", line 471, in run_until_complete
    self.run_forever()
  File "/usr/lib/python3.6/asyncio/base_events.py", line 438, in run_forever
    self._run_once()
  File "/usr/lib/python3.6/asyncio/base_events.py", line 1451, in _run_once
    handle._run()
  File "/usr/lib/python3.6/asyncio/events.py", line 145, in _run
    self._callback(*self._args)
  File "/usr/local/lib/python3.6/dist-packages/websockets/protocol.py", line 795, in transfer_data
    message = await self.read_message()
  File "/usr/local/lib/python3.6/dist-packages/websockets/protocol.py", line 863, in read_message
    frame = await self.read_data_frame(max_size=self.max_size)
  File "/usr/local/lib/python3.6/dist-packages/websockets/protocol.py", line 938, in read_data_frame
    frame = await self.read_frame(max_size)
  File "/usr/local/lib/python3.6/dist-packages/websockets/protocol.py", line 1020, in read_frame
    logger.debug("%s < %r", self.side, frame)
  File "/usr/lib/python3.6/logging/__init__.py", line 1296, in debug
    self._log(DEBUG, msg, args, **kwargs)
  File "/usr/lib/python3.6/logging/__init__.py", line 1444, in _log
    self.handle(record)
  File "/usr/lib/python3.6/logging/__init__.py", line 1454, in handle
    self.callHandlers(record)
  File "/usr/lib/python3.6/logging/__init__.py", line 1516, in callHandlers
    hdlr.handle(record)
  File "/usr/lib/python3.6/logging/__init__.py", line 865, in handle
    self.emit(record)
  File "/usr/lib/python3.6/logging/__init__.py", line 996, in emit
    stream.write(msg)
KeyboardInterrupt
Traceback (most recent call last):
  File "/usr/local/lib/python3.6/dist-packages/websockets/protocol.py", line 806, in transfer_data
    await asyncio.shield(self._put_message_waiter)
concurrent.futures._base.CancelledError

The above exception was the direct cause of the following exception:

Traceback (most recent call last):
  File "queue_process.py", line 27, in queue_client
    current_turn = await socket.recv()
  File "/usr/local/lib/python3.6/dist-packages/websockets/protocol.py", line 484, in recv
    await self.ensure_open()
  File "/usr/local/lib/python3.6/dist-packages/websockets/protocol.py", line 780, in ensure_open
    raise self.connection_closed_exc()
websockets.exceptions.ConnectionClosedError: code = 1006 (connection closed abnormally [internal]), no reason
Traceback (most recent call last):
  File "/usr/local/lib/python3.6/dist-packages/websockets/protocol.py", line 806, in transfer_data
    await asyncio.shield(self._put_message_waiter)
concurrent.futures._base.CancelledError

The above exception was the direct cause of the following exception:

Traceback (most recent call last):
  File "queue_process.py", line 27, in queue_client
    current_turn = await socket.recv()
  File "/usr/local/lib/python3.6/dist-packages/websockets/protocol.py", line 484, in recv
    await self.ensure_open()
  File "/usr/local/lib/python3.6/dist-packages/websockets/protocol.py", line 780, in ensure_open
    raise self.connection_closed_exc()
websockets.exceptions.ConnectionClosedError: code = 1006 (connection closed abnormally [internal]), no reason
